2024-01-12 15:30:12,310 ERROR: Exception on /profile [GET] [in /home/algoar/Documents/M12/.venv/lib/python3.11/site-packages/flask/app.py:825]
Traceback (most recent call last):
  File "/home/algoar/Documents/M12/.venv/lib/python3.11/site-packages/flask/app.py", line 1455, in wsgi_app
    response = self.full_dispatch_request()
               ^^^^^^^^^^^^^^^^^^^^^^^^^^^^
  File "/home/algoar/Documents/M12/.venv/lib/python3.11/site-packages/flask/app.py", line 869, in full_dispatch_request
    rv = self.handle_user_exception(e)
         ^^^^^^^^^^^^^^^^^^^^^^^^^^^^^
  File "/home/algoar/Documents/M12/.venv/lib/python3.11/site-packages/flask/app.py", line 867, in full_dispatch_request
    rv = self.dispatch_request()
         ^^^^^^^^^^^^^^^^^^^^^^^
  File "/home/algoar/Documents/M12/.venv/lib/python3.11/site-packages/flask_debugtoolbar/__init__.py", line 157, in dispatch_request
    return view_func(**req.view_args)
           ^^^^^^^^^^^^^^^^^^^^^^^^^^
  File "/home/algoar/Documents/M12/.venv/lib/python3.11/site-packages/flask_login/utils.py", line 290, in decorated_view
    return current_app.ensure_sync(func)(*args, **kwargs)
           ^^^^^^^^^^^^^^^^^^^^^^^^^^^^^^^^^^^^^^^^^^^^^^
  File "/home/algoar/Documents/M12/wannapop/routes_main.py", line 23, in profile
    blocked_user = BlockedUser.query.filter_by(user_id=current_user.id).first()
                   ^^^^^^^^^^^^^^^^^^^^^^^^^^^^^^^^^^^^^^^^^^^^^^^^^^^^^^^^^^^^
  File "/home/algoar/Documents/M12/.venv/lib/python3.11/site-packages/sqlalchemy/orm/query.py", line 2748, in first
    return self.limit(1)._iter().first()  # type: ignore
           ^^^^^^^^^^^^^^^^^^^^^
  File "/home/algoar/Documents/M12/.venv/lib/python3.11/site-packages/sqlalchemy/orm/query.py", line 2847, in _iter
    result: Union[ScalarResult[_T], Result[_T]] = self.session.execute(
                                                  ^^^^^^^^^^^^^^^^^^^^^
  File "/home/algoar/Documents/M12/.venv/lib/python3.11/site-packages/sqlalchemy/orm/session.py", line 2308, in execute
    return self._execute_internal(
           ^^^^^^^^^^^^^^^^^^^^^^^
  File "/home/algoar/Documents/M12/.venv/lib/python3.11/site-packages/sqlalchemy/orm/session.py", line 2178, in _execute_internal
    bind = self.get_bind(**bind_arguments)
           ^^^^^^^^^^^^^^^^^^^^^^^^^^^^^^^
  File "/home/algoar/Documents/M12/.venv/lib/python3.11/site-packages/flask_sqlalchemy/session.py", line 53, in get_bind
    engines = self._db.engines
              ^^^^^^^^^^^^^^^^
  File "/home/algoar/Documents/M12/.venv/lib/python3.11/site-packages/flask_sqlalchemy/extension.py", line 690, in engines
    raise RuntimeError(
RuntimeError: The current Flask app is not registered with this 'SQLAlchemy' instance. Did you forget to call 'init_app', or did you create multiple 'SQLAlchemy' instances?
2024-01-12 15:34:35,980 INFO: Aplicació iniciada [in /home/algoar/Documents/M12/wannapop/__init__.py:60]
2024-01-12 15:34:35,985 INFO: Aplicació iniciada [in /home/algoar/Documents/M12/wannapop/__init__.py:60]
2024-01-12 15:34:35,985 INFO: Aplicació iniciada [in /home/algoar/Documents/M12/wannapop/__init__.py:60]
2024-01-12 18:26:18,386 INFO: Aplicació iniciada [in /home/algoar/Documents/M12/wannapop/__init__.py:60]
2024-01-12 18:26:18,390 INFO: Aplicació iniciada [in /home/algoar/Documents/M12/wannapop/__init__.py:60]
2024-01-12 18:26:18,390 INFO: Aplicació iniciada [in /home/algoar/Documents/M12/wannapop/__init__.py:60]
2024-01-12 18:34:29,313 INFO: Aplicació iniciada [in /home/algoar/Documents/M12/wannapop/__init__.py:58]
2024-01-12 18:34:29,318 INFO: Aplicació iniciada [in /home/algoar/Documents/M12/wannapop/__init__.py:58]
2024-01-12 18:34:29,318 INFO: Aplicació iniciada [in /home/algoar/Documents/M12/wannapop/__init__.py:58]
2024-01-12 18:34:44,896 INFO: Aplicació iniciada [in /home/algoar/Documents/M12/wannapop/__init__.py:58]
2024-01-12 18:34:44,900 INFO: Aplicació iniciada [in /home/algoar/Documents/M12/wannapop/__init__.py:58]
2024-01-12 18:34:44,900 INFO: Aplicació iniciada [in /home/algoar/Documents/M12/wannapop/__init__.py:58]
2024-01-12 18:34:47,635 INFO: Aplicació iniciada [in /home/algoar/Documents/M12/wannapop/__init__.py:58]
2024-01-12 18:34:47,639 INFO: Aplicació iniciada [in /home/algoar/Documents/M12/wannapop/__init__.py:58]
2024-01-12 18:34:47,639 INFO: Aplicació iniciada [in /home/algoar/Documents/M12/wannapop/__init__.py:58]
2024-01-12 18:35:44,872 INFO: Aplicació iniciada [in /home/algoar/Documents/M12/wannapop/__init__.py:58]
2024-01-12 18:35:44,877 INFO: Aplicació iniciada [in /home/algoar/Documents/M12/wannapop/__init__.py:58]
2024-01-12 18:35:44,877 INFO: Aplicació iniciada [in /home/algoar/Documents/M12/wannapop/__init__.py:58]
